Workbook

Sheet Cover
B2: Dhaka Tesla Pool — SRS Traceability Tracker
B3: Share a seat. Split the fare. Survive Dhaka traffic.
B5: Document | C5: DTP-SRS-001 — docs/SRS.md (ISO/IEC/IEEE 29148:2018, tailored)
B6: SRS version | C6: 0.3 (Draft for review) — see SRS revision history
B7: Author | C7: Golam Mahadi Ahmed
B8: Created | C8: 2026-09-23
B9: Source brief | C9: Dhaka_Tesla_Pool_PRD_Internship.pdf (RoBenDevs)
B10: Last updated | C10: 2026-09-24 — Phase 4 (feature/ride-request): state machines, audit trail, ride requests, expiry, unmatched cancellation
B11: How to maintain this workbook
B12: • | C12: Requirement text lives in docs/SRS.md; change it there first, then mirror the row here (same ID).
B13: • | C13: Yellow cells are the ones to edit: Status, Evidence and Notes columns on each sheet (dropdowns enforce allowed values).
B14: • | C14: Requirement status flow: Proposed → Approved (SRS reviewed) → In Progress → Implemented (merged to master) → Verified (linked tests pass).
B15: • | C15: When a test is written, set Test_Cases.Status and put the test file path in 'Test file / evidence'.
B16: • | C16: When a task is merged, set Implementation_Tasks.Status = Done and paste the commit hash / PR link.
B17: • | C17: Never reuse or delete an ID — set Status = Withdrawn instead. Blue numbers on Zones_Distances / Fare_Calculator are reference inputs.
B19: Requirements by type | F19: By priority
B20: Type | C20: Count | D20: of which Must | F20: Priority | G20: Count
B21: FR — Functional | C21: =COUNTIF(Requirements_RTM!$B$2:$B$142,"FR") | D21: =COUNTIFS(Requirements_RTM!$B$2:$B$142,"FR",Requirements_RTM!$E$2:$E$142,"M") | F21: M | G21: =COUNTIF(Requirements_RTM!$E$2:$E$142,"M")
B22: BR — Business rule | C22: =COUNTIF(Requirements_RTM!$B$2:$B$142,"BR") | D22: =COUNTIFS(Requirements_RTM!$B$2:$B$142,"BR",Requirements_RTM!$E$2:$E$142,"M") | F22: S | G22: =COUNTIF(Requirements_RTM!$E$2:$E$142,"S")
B23: NFR — Non-functional | C23: =COUNTIF(Requirements_RTM!$B$2:$B$142,"NFR") | D23: =COUNTIFS(Requirements_RTM!$B$2:$B$142,"NFR",Requirements_RTM!$E$2:$E$142,"M") | F23: C | G23: =COUNTIF(Requirements_RTM!$E$2:$E$142,"C")
B24: DC — Design constraint | C24: =COUNTIF(Requirements_RTM!$B$2:$B$142,"DC") | D24: =COUNTIFS(Requirements_RTM!$B$2:$B$142,"DC",Requirements_RTM!$E$2:$E$142,"M") | F24: W | G24: =COUNTIF(Requirements_RTM!$E$2:$E$142,"W")
B25: DR — Delivery / process | C25: =COUNTIF(Requirements_RTM!$B$2:$B$142,"DR") | D25: =COUNTIFS(Requirements_RTM!$B$2:$B$142,"DR",Requirements_RTM!$E$2:$E$142,"M")
B26: Total | C26: =SUM(C21:C25) | D26: =SUM(D21:D25)
B28: Requirements by status | E28: Test cases by status | H28: Tasks by status
B29: Status | C29: Count | E29: Status | F29: Count | H29: Status | I29: Count
B30: Proposed | C30: =COUNTIF(Requirements_RTM!$M$2:$M$142,"Proposed") | E30: Not Written | F30: =COUNTIF(Test_Cases!$I$2:$I$52,"Not Written") | H30: Not Started | I30: =COUNTIF(Implementation_Tasks!$G$2:$G$28,"Not Started")
B31: Approved | C31: =COUNTIF(Requirements_RTM!$M$2:$M$142,"Approved") | E31: Written | F31: =COUNTIF(Test_Cases!$I$2:$I$52,"Written") | H31: In Progress | I31: =COUNTIF(Implementation_Tasks!$G$2:$G$28,"In Progress")
B32: In Progress | C32: =COUNTIF(Requirements_RTM!$M$2:$M$142,"In Progress") | E32: Passing | F32: =COUNTIF(Test_Cases!$I$2:$I$52,"Passing") | H32: In Review | I32: =COUNTIF(Implementation_Tasks!$G$2:$G$28,"In Review")
B33: Implemented | C33: =COUNTIF(Requirements_RTM!$M$2:$M$142,"Implemented") | E33: Failing | F33: =COUNTIF(Test_Cases!$I$2:$I$52,"Failing") | H33: Done | I33: =COUNTIF(Implementation_Tasks!$G$2:$G$28,"Done")
B34: Verified | C34: =COUNTIF(Requirements_RTM!$M$2:$M$142,"Verified") | E34: Blocked | F34: =COUNTIF(Test_Cases!$I$2:$I$52,"Blocked") | H34: Blocked | I34: =COUNTIF(Implementation_Tasks!$G$2:$G$28,"Blocked")
B35: Deferred | C35: =COUNTIF(Requirements_RTM!$M$2:$M$142,"Deferred")
B36: Withdrawn | C36: =COUNTIF(Requirements_RTM!$M$2:$M$142,"Withdrawn")
B38: Traceability health checks (all should be 0)
B39: Check | C39: Value | D39: Target | E39: Result
B40: Test-verified requirements with no test case | C40: =COUNTIFS(Requirements_RTM!$I$2:$I$142,"*T*",Requirements_RTM!$J$2:$J$142,"",Requirements_RTM!$E$2:$E$142,"<>W") | D40: 0 | E40: =IF(C40=D40,"PASS","FIX")
B41: Requirements (not Won't) with no implementation task | C41: =COUNTIFS(Requirements_RTM!$K$2:$K$142,"",Requirements_RTM!$E$2:$E$142,"<>W") | D41: 0 | E41: =IF(C41=D41,"PASS","FIX")
B42: Requirements with no acceptance criteria | C42: =COUNTIFS(Requirements_RTM!$H$2:$H$142,"") | D42: 0 | E42: =IF(C42=D42,"PASS","FIX")
B43: PRD sections with a coverage GAP | C43: =COUNTIF(PRD_Coverage!$E$2:$E$20,"GAP") | D43: 0 | E43: =IF(C43=D43,"PASS","FIX")
B44: Fare calculator mismatches | C44: =COUNTIF(Fare_Calculator!$N$12:$N$21,"MISMATCH") | D44: 0 | E44: =IF(C44=D44,"PASS","FIX")
B45: Zone distance asymmetries | C45: =Zones_Distances!D27 | D45: 0 | E45: =IF(C45=D45,"PASS","FIX")

Sheet Requirements_RTM
A1: Req ID | B1: Type | C1: Module | D1: Requirement statement | E1: Priority (MoSCoW) | F1: PRD § | G1: SRS § | H1: Acceptance criteria | I1: Verification (T/D/I) | J1: Test IDs | K1: Task IDs | L1: Feature branch(es) | M1: Status | N1: Evidence (commit / PR / test run) | O1: Notes | P1: PRD key (helper)
A2: FR-AUTH-01 | B2: FR | C2: AUTH | D2: The system shall let a new passenger sign up with full name, phone number, e-mail, password and an optional self-declared gender (FEMALE, MALE or PREFER_NOT_TO_SAY; default PREFER_NOT_TO_SAY). | E2: M | F2: 3 | G2: 4.1 | H2: Valid input creates a PASSENGER account and a TeslaPay wallet with ৳0 balance. A duplicate e-mail or phone returns 409 and no account is created. A password shorter than 8 characters returns 400. | I2: T | J2: TC-31, TC-50 | K2: T-08 | L2: feature/passenger-auth | M2: Implemented | N2: POST /api/auth/signup; test/auth/sign-up.test.ts — feature/passenger-auth | P2: =","&SUBSTITUTE(F2," ","")&","
A3: FR-AUTH-02 | B3: FR | C3: AUTH | D3: The system shall let passengers and drivers sign in with e-mail (or phone) and password. | E3: M | F3: 3 | G3: 4.1 | H3: Correct credentials give an authenticated session that identifies the user and role. Wrong credentials return 401 with a generic message that does not reveal whether the account exists. | I3: T | J3: TC-32 | K3: T-08 | L3: feature/passenger-auth | M3: Implemented | N3: POST /api/auth/login (e-mail or phone); test/auth/sessions.test.ts — feature/passenger-auth | P3: =","&SUBSTITUTE(F3," ","")&","
A4: FR-AUTH-03 | B4: FR | C4: AUTH | D4: The system shall let a signed-in user sign out, which invalidates the client session. | E4: M | F4: 3 | G4: 4.1 | H4: After sign-out, protected endpoints return 401 for that session. | I4: T | J4: TC-32 | K4: T-08 | L4: feature/passenger-auth | M4: Implemented | N4: POST /api/auth/logout revokes the session — feature/passenger-auth | P4: =","&SUBSTITUTE(F4," ","")&","
A5: FR-AUTH-04 | B5: FR | C5: AUTH | D5: The system shall expose the current user's profile and role to the frontend. | E5: M | F5: 3 | G5: 4.1 | H5: GET /me returns id, name and role (plus the vehicle, for drivers). Without a session it returns 401. | I5: T | J5: TC-32 | K5: T-08 | L5: feature/passenger-auth | M5: Implemented | N5: GET /api/auth/me (vehicle for drivers) — feature/passenger-auth | P5: =","&SUBSTITUTE(F5," ","")&","
A6: FR-AUTH-05 | B6: FR | C6: AUTH | D6: The frontend shall route users to the dashboard for their role and block access to the other role's pages. | E6: M | F6: 3 | G6: 4.1 | H6: A passenger who opens a driver URL is redirected or sees 403. The API enforces the same rule (NFR-SEC-03). | I6: T, D | J6: TC-04 | K6: T-09, T-19 | L6: feature/passenger-auth, feature/passenger-ui | M6: In Progress | N6: API role guards done (test/auth/access.test.ts); web routing in feature/passenger-ui — feature/passenger-auth | P6: =","&SUBSTITUTE(F6," ","")&","
A7: FR-AUTH-06 | B7: FR | C7: AUTH | D7: Driver accounts, each linked to exactly one Tesla, shall be provisioned by seed data. | E7: M | F7: 3, 6 | G7: 4.1 | H7: After seeding, Jashim can sign in and sees Bullet (capacity 3). | I7: T | J7: TC-37 | K7: T-07 | L7: feature/db-schema | M7: Implemented | N7: Jashim/Bullet and Kamal/Toofan seeded — feature/db-schema | P7: =","&SUBSTITUTE(F7," ","")&","
A8: FR-AUTH-07 | B8: FR | C8: AUTH | D8: The system may allow driver self-registration with vehicle details. | E8: W | F8: 3 | G8: 4.1 | H8: Not in MVP (A-05). | I8: — | M8: Deferred | P8: =","&SUBSTITUTE(F8," ","")&","
A9: FR-PAX-01 | B9: FR | C9: PAX | D9: The system shall provide the list of supported zones for pickup and destination selection. | E9: M | F9: 4 | G9: 4.2 | H9: GET /zones returns every seeded zone with code, name and coordinates. The UI offers only these zones. | I9: T | J9: TC-35 | K9: T-11 | L9: feature/zones-fares | M9: Implemented | N9: GET /api/zones; test/zones/zones.test.ts — feature/zones-fares | P9: =","&SUBSTITUTE(F9," ","")&","
A10: FR-PAX-02 | B10: FR | C10: PAX | D10: The system shall show a fare estimate for a pickup, destination and seat count before the passenger confirms. The estimate shall show both the solo fare and the "if pooled" fare. | E10: M | F10: 3, 5 | G10: 4.2 | H10: For Nusrat (Banani→Mohakhali, 1 seat), the estimate shows ৳75.00 solo and ৳66.00 if pooled, with the breakdown shown (BR-10). | I10: T | J10: TC-35 | K10: T-11, T-20 | L10: feature/zones-fares, feature/passenger-ui | M10: In Progress | N10: POST /api/fares/estimate returns solo and pooled (TC-35); form in feature/passenger-ui — feature/zones-fares | P10: =","&SUBSTITUTE(F10," ","")&","
A11: FR-PAX-03 | B11: FR | C11: PAX | D11: A passenger shall be able to create a ride request with pickup zone, destination zone, seats (1 to the maximum vehicle capacity), pool opt-in (default: yes), same-gender co-riders only (default: no) and payment method (CASH or TESLAPAY). | E11: M | F11: 3 | G11: 4.2 | H11: Valid input creates a request in REQUESTED status and records an audit entry. Pickup equal to destination returns 400. Seats outside the valid range return 400. An unknown zone returns 400. | I11: T | J11: TC-24, TC-33, TC-50 | K11: T-13 | L11: feature/ride-request | M11: Implemented | N11: POST /api/rides; test/rides/request.test.ts (TC-33) — feature/ride-request | P11: =","&SUBSTITUTE(F11," ","")&","
A12: FR-PAX-04 | B12: FR | C12: PAX | D12: The system shall reject a new request while the passenger already has an active request. | E12: M | F12: 3, 12 | G12: 4.2 | H12: A second request returns 409 ACTIVE_REQUEST_EXISTS. This is enforced at database level as well (NFR-CON-04). | I12: T | J12: TC-18 | K12: T-13 | L12: feature/ride-request | M12: Implemented | N12: 409 ACTIVE_REQUEST_EXISTS with the existing ride id; double submit covered (TC-18) — feature/ride-request | P12: =","&SUBSTITUTE(F12," ","")&","
A13: FR-PAX-05 | B13: FR | C13: PAX | D13: When TeslaPay is selected, the system shall reject the request if the wallet balance is lower than the estimated solo fare. | E13: S | F13: 5 | G13: 4.2 | H13: With a balance of ৳50 and a solo fare of ৳75, the request is rejected with 422 INSUFFICIENT_BALANCE. | I13: T | J13: TC-28 | K13: T-13 | L13: feature/ride-request | M13: Implemented | N13: 422 INSUFFICIENT_BALANCE against the solo estimate; Rafiq test — feature/ride-request | P13: =","&SUBSTITUTE(F13," ","")&","
A14: FR-PAX-06 | B14: FR | C14: PAX | D14: The passenger shall be able to view their current ride: status, status timeline, pickup and destination, seats, fare (estimate or locked), payment method, driver name, Tesla name and plate once matched, whether the ride is shared, and the number of co-riders. | E14: M | F14: 2, 3 | G14: 4.2 | H14: Nusrat sees "Shared ride · 1 co-rider" and only her own fare. No other passenger's name, fare or destination appears anywhere in her API responses (A-09). | I14: T, D | J14: TC-13 | K14: T-13, T-20 | L14: feature/ride-request, feature/passenger-ui | M14: In Progress | N14: GET /api/rides?scope=active and /:id with driver, Tesla, co-rider count, badge — feature/ride-request; screen in feature/passenger-ui | P14: =","&SUBSTITUTE(F14," ","")&","
A15: FR-PAX-07 | B15: FR | C15: PAX | D15: The passenger's ride view shall refresh status automatically without a manual page reload. | E15: M | F15: 3 | G15: 4.2 | H15: A status change made by the driver appears for the passenger within 5 s (polling, A-11). | I15: D | J15: TC-41 | K15: T-20 | L15: feature/passenger-ui | M15: Proposed | P15: =","&SUBSTITUTE(F15," ","")&","
A16: FR-PAX-08 | B16: FR | C16: PAX | D16: A passenger shall be able to cancel their own request when the cancellation rules allow it (BR-07). If a fee applies, the fee shall be shown and confirmed before cancelling. | E16: M | F16: 3, 12 | G16: 4.2 | H16: Cancelling in REQUESTED or MATCHED is free. Cancelling in DRIVER_ARRIVED shows "৳20.00 cancellation fee" and requires confirmation. Cancelling in STARTED, COMPLETED, CANCELLED or EXPIRED returns 409 INVALID_STATE_TRANSITION. | I16: T | J16: TC-05 | K16: T-13, T-20 | L16: feature/ride-request, feature/passenger-ui | M16: In Progress | N16: POST /api/rides/:id/cancel: REQUESTED free, STARTED/terminal 409 — feature/ride-request; MATCHED and DRIVER_ARRIVED (fee) later | P16: =","&SUBSTITUTE(F16," ","")&","
A17: FR-PAX-09 | B17: FR | C17: PAX | D17: The passenger shall be able to view their ride history (newest first, paginated), showing date, route, seats, final status, final fare, payment method and whether the ride was shared. | E17: M | F17: 3 | G17: 4.2 | H17: The history contains only the passenger's own requests. An empty history shows an empty state. | I17: T, D | J17: TC-39 | K17: T-13, T-21 | L17: feature/ride-request, feature/passenger-ui | M17: In Progress | N17: GET /api/rides?scope=history, newest first, cursor paging (TC-39) — feature/ride-request; screen in feature/passenger-ui | P17: =","&SUBSTITUTE(F17," ","")&","
A18: FR-PAX-10 | B18: FR | C18: PAX | D18: The passenger shall be able to open a past ride and see its full status timeline and fare breakdown. | E18: S | F18: 2, 3 | G18: 4.2 | H18: The timeline lists every transition with its timestamp, taken from the audit trail. | I18: T, D | J18: TC-39 | K18: T-13, T-21 | L18: feature/ride-request, feature/passenger-ui | M18: In Progress | N18: GET /api/rides/:id timeline from status_history — feature/ride-request; screen in feature/passenger-ui | P18: =","&SUBSTITUTE(F18," ","")&","
A19: FR-PAX-11 | B19: FR | C19: PAX | D19: A passenger whose declared gender is FEMALE or MALE may request a same-gender ride (co-riders of their gender only). The option shall be unavailable to passengers who declared PREFER_NOT_TO_SAY, and it requires pool opt-in. The ride view shall show a "Women-only ride" / "Men-only ride" badge. | E19: S | F19: 2, 3 | G19: 4.2 | H19: Shirin (FEMALE) can set the option. A PREFER_NOT_TO_SAY passenger setting it gets 400 VALIDATION_ERROR, as does setting it with pool opt-in = false. No co-rider gender is ever returned by passenger APIs. | I19: T | J19: TC-50 | K19: T-13, T-20 | L19: feature/ride-request, feature/passenger-ui | M19: In Progress | N19: Option validation (TC-50 parts 2-3) — feature/ride-request; matching in feature/tesla-pooling, badge in the UI | O19: Added in SRS v0.3 | P19: =","&SUBSTITUTE(F19," ","")&","
A20: FR-DRV-01 | B20: FR | C20: DRV | D20: A signed-in driver shall see their Tesla's name, plate and seat capacity. | E20: M | F20: 3 | G20: 4.3 | H20: Jashim sees "Bullet · DHAKA-TESLA-11 · 3 seats". | I20: T, D | J20: TC-40 | K20: T-14, T-22 | L20: feature/tesla-pooling, feature/driver-ui | M20: Proposed | P20: =","&SUBSTITUTE(F20," ","")&","
A21: FR-DRV-02 | B21: FR | C21: DRV | D21: A driver shall be able to go online, selecting their current zone, and go offline. | E21: M | F21: 3 | G21: 4.3 | H21: Going online sets the driver ONLINE in the chosen zone. Going offline sets OFFLINE. Both are audited. | I21: T | J21: TC-22 | K21: T-14, T-22 | L21: feature/tesla-pooling, feature/driver-ui | M21: Proposed | P21: =","&SUBSTITUTE(F21," ","")&","
A22: FR-DRV-03 | B22: FR | C22: DRV | D22: The system shall prevent a driver from going offline while they have an active pool. | E22: M | F22: 3 | G22: 4.3 | H22: Returns 409 ACTIVE_POOL_EXISTS. The UI disables the toggle and explains why. | I22: T | J22: TC-22 | K22: T-14 | L22: feature/tesla-pooling | M22: Proposed | P22: =","&SUBSTITUTE(F22," ","")&","
A23: FR-DRV-04 | B23: FR | C23: DRV | D23: An online driver shall see relevant requests. With no active pool, these are REQUESTED, non-expired requests whose pickup zone is the driver's current zone and whose seats are at most the vehicle capacity. With an OPEN pool, these are only requests compatible with that pool (BR-02). Each shows pickup, destination, seats, pool opt-in, estimated fare and age. | E23: M | F23: 3, 4 | G23: 4.3 | H23: With Jashim online in Banani and Nusrat's request pending, the list contains Nusrat. After accepting Nusrat, it contains Rafiq (compatible) and does not contain a Banani→Uttara request. An offline driver gets 409 DRIVER_OFFLINE. | I23: T | J23: TC-23 | K23: T-14, T-22 | L23: feature/tesla-pooling, feature/driver-ui | M23: Proposed | P23: =","&SUBSTITUTE(F23," ","")&","
A24: FR-DRV-05 | B24: FR | C24: DRV | D24: A driver shall be able to accept a relevant request. If the driver has no active pool, a new pool is created. If the driver has an OPEN pool, the request is added to it. | E24: M | F24: 3 | G24: 4.3 | H24: The request moves to MATCHED and becomes a pool member, and occupied seats go up by its seat count, all in one transaction. The server re-checks every rule (BR-01…BR-05) at accept time. A rule violation returns 409 or 422 with a specific code. | I24: T | J24: TC-25 | K24: T-15 | L24: feature/tesla-pooling | M24: Proposed | P24: =","&SUBSTITUTE(F24," ","")&","
A25: FR-DRV-06 | B25: FR | C25: DRV | D25: The driver shall see the active pool: status, occupied and free seats, and for each member the passenger's name, pickup, destination, seats, status, payment method and fare, plus a badge when the pool is gender-restricted. | E25: M | F25: 2, 3 | G25: 4.3 | H25: With Nusrat and Rafiq matched, Jashim sees "2 / 3 seats occupied" and both members with their fares. | I25: T, D | J25: TC-25, TC-47 | K25: T-17, T-22 | L25: feature/driver-flow, feature/driver-ui | M25: Proposed | P25: =","&SUBSTITUTE(F25," ","")&","
A26: FR-DRV-07 | B26: FR | C26: DRV | D26: The driver shall be able to mark the pool as arrived at the pickup zone. | E26: M | F26: 3 | G26: 4.3 | H26: The pool moves OPEN→DRIVER_ARRIVED, and every MATCHED member moves to DRIVER_ARRIVED. | I26: T | J26: TC-25 | K26: T-17, T-22 | L26: feature/driver-flow, feature/driver-ui | M26: Proposed | P26: =","&SUBSTITUTE(F26," ","")&","
A27: FR-DRV-08 | B27: FR | C27: DRV | D27: The driver shall be able to start the trip. | E27: M | F27: 3 | G27: 4.3 | H27: The pool moves DRIVER_ARRIVED→STARTED, and every DRIVER_ARRIVED member moves to STARTED. Fares are locked (BR-12). Starting is rejected if the pool has no member in DRIVER_ARRIVED. | I27: T | J27: TC-25 | K27: T-17, T-22 | L27: feature/driver-flow, feature/driver-ui | M27: Proposed | P27: =","&SUBSTITUTE(F27," ","")&","
A28: FR-DRV-09 | B28: FR | C28: DRV | D28: The driver shall be able to drop off (complete) each passenger individually, in any order. | E28: M | F28: 3 | G28: 4.3 | H28: The member moves STARTED→COMPLETED and payment is settled (BR-15/BR-16). When the last member is completed, the pool automatically becomes COMPLETED and the driver's current zone is set to the last drop-off zone. | I28: T | J28: TC-25 | K28: T-17, T-22 | L28: feature/driver-flow, feature/driver-ui | M28: Proposed | P28: =","&SUBSTITUTE(F28," ","")&","
A29: FR-DRV-10 | B29: FR | C29: DRV | D29: For cash payments, the driver shall be able to mark cash as collected. | E29: M | F29: 5 | G29: 4.3 | H29: The payment status for that member becomes PAID with method CASH. This action is audited. | I29: T | J29: TC-27 | K29: T-18, T-22 | L29: feature/teslapay-wallet, feature/driver-ui | M29: Proposed | P29: =","&SUBSTITUTE(F29," ","")&","
A30: FR-DRV-11 | B30: FR | C30: DRV | D30: The driver shall be able to cancel the pool before the trip starts. | E30: M | F30: 3 | G30: 4.3 | H30: The pool moves to CANCELLED. Active members move back to REQUESTED so another driver can pick them up, and passengers are not charged. Cancelling after STARTED returns 409. | I30: T | J30: TC-15 | K30: T-17, T-22 | L30: feature/driver-flow, feature/driver-ui | M30: Proposed | P30: =","&SUBSTITUTE(F30," ","")&","
A31: FR-DRV-12 | B31: FR | C31: DRV | D31: The driver shall be able to mark an arrived passenger as a no-show after a 5-minute wait. | E31: C | F31: 3 | G31: 4.3 | H31: The member moves DRIVER_ARRIVED→CANCELLED with reason NO_SHOW, and the ৳20 fee applies (BR-07). | I31: T | J31: TC-43 | K31: T-17 | L31: feature/driver-flow | M31: Proposed | P31: =","&SUBSTITUTE(F31," ","")&","
... A40: FR-POOL-08 | B40: FR | C40: POOL | D40: A pool shall be completed automatically when its last on-board member is completed. | E40: M | F40: 3 | G40: 4.4 | H40: The pool status is COMPLETED and completed_at is set. | I40: T | J40: TC-25 | K40: T-17 | L40: feature/driver-flow | M40: Proposed | P40: =","&SUBSTITUTE(F40," ","")&","
A41: FR-POOL-09 | B41: FR | C41: POOL | D41: A ride request shall belong to at most one active pool at a time. | E41: M | F41: 3 | G41: 4.4 | H41: Enforced by a unique constraint. Two drivers accepting the same request concurrently gives exactly one success; the other gets 409 INVALID_STATE_TRANSITION. | I41: T | J41: TC-06 | K41: T-06, T-15 | L41: feature/db-schema, feature/tesla-pooling | M41: In Progress | N41: pool_members_one_active_membership index tested; accept flow in feature/tesla-pooling — feature/db-schema | P41: =","&SUBSTITUTE(F41," ","")&","
A42: FR-POOL-10 | B42: FR | C42: POOL | D42: Pool membership shall be explicit and queryable. For any pool it shall be possible to list its members and each member's seats and status. | E42: M | F42: 3 | G42: 4.4 | H42: The driver's pool view and the database both show the membership. | I42: T | J42: TC-25 | K42: T-06 | L42: feature/db-schema | M42: In Progress | N42: pool_members table; roster endpoint in feature/driver-flow — feature/db-schema | P42: =","&SUBSTITUTE(F42," ","")&","
A43: FR-POOL-11 | B43: FR | C43: POOL | D43: Gender restrictions (BR-18) shall be enforced on the server at accept time, under the same pool lock as capacity. | E43: S | F43: 2, 4 | G43: 4.4 | H43: With Shirin (same-gender option) in Bullet's pool, accepting Rafiq returns 422 NOT_COMPATIBLE with reason GENDER_RESTRICTED, and accepting Nusrat succeeds. Accepting a same-gender request from Shirin into a pool containing Rafiq returns the same 422. | I43: T | J43: TC-47, TC-48, TC-51 | K43: T-15 | L43: feature/tesla-pooling | M43: Proposed | O43: Added in SRS v0.3 | P43: =","&SUBSTITUTE(F43," ","")&","
A44: FR-POOL-12 | B44: FR | C44: POOL | D44: A pool's gender restriction shall be recalculated whenever a member leaves before the trip starts. | E44: S | F44: 3 | G44: 4.4 | H44: If Shirin was the only member requesting it and she cancels, the restriction returns to NONE and Rafiq becomes acceptable. | I44: T | J44: TC-49 | K44: T-17 | L44: feature/driver-flow | M44: Proposed | O44: Added in SRS v0.3 | P44: =","&SUBSTITUTE(F44," ","")&","
A45: FR-FARE-01 | B45: FR | C45: FARE | D45: The system shall calculate each passenger's fare with the formula in BR-10, using the zone distance table (BR-09). | E45: M | F45: 5 | G45: 4.5 | H45: The worked examples in §6.4 are reproduced exactly by unit tests. | I45: T | J45: TC-03, TC-12 | K45: T-10 | L45: feature/zones-fares | M45: Implemented | N45: domain/fare.ts computeFare; test/domain/fare.test.ts (TC-03, TC-12) — feature/zones-fares | P45: =","&SUBSTITUTE(F45," ","")&","
A46: FR-FARE-02 | B46: FR | C46: FARE | D46: At request time, the system shall store and show an estimate: the solo fare, plus the pooled fare if the passenger opted in. | E46: M | F46: 5 | G46: 4.5 | H46: The request record stores estimated_fare_paisa (solo). The response includes both figures. | I46: T | J46: TC-35 | K46: T-11 | L46: feature/zones-fares | M46: Implemented | N46: Estimate endpoint (feature/zones-fares); estimated_fare_paisa stored on each request and both figures in the ride view — feature/ride-request | P46: =","&SUBSTITUTE(F46," ","")&","
A47: FR-FARE-03 | B47: FR | C47: FARE | D47: At trip start, the system shall lock each on-board member's final fare and store the rates used (base, per-km, discount rate, distance, seats, pooled flag). | E47: M | F47: 2, 5 | G47: 4.5 | H47: Changing the rate configuration afterwards does not change any locked fare. | I47: T | J47: TC-09, TC-11 | K47: T-17 | L47: feature/driver-flow | M47: Proposed | P47: =","&SUBSTITUTE(F47," ","")&","
A48: FR-FARE-04 | B48: FR | C48: FARE | D48: The passenger and driver views shall show a fare breakdown: base, distance charge, pool discount, seats and total. | E48: M | F48: 5 | G48: 4.5 | H48: The numbers in the breakdown add up to the total shown. | I48: T, D | J48: TC-35 | K48: T-11 | L48: feature/zones-fares | M48: In Progress | N48: API returns base, distance charge, discount, seats, total (TC-35); views in the UI branches — feature/zones-fares | P48: =","&SUBSTITUTE(F48," ","")&","
...

Sheet Test_Cases
A1: Test ID | B1: Title | C1: Req IDs | D1: Type | E1: PRD §12 area | F1: Preconditions (reference personas) | G1: Steps | H1: Expected result | I1: Status | J1: Test file / evidence | K1: Last run
A2: TC-01 | B2: Bullet's capacity can never be exceeded | C2: FR-POOL-02, BR-01 | D2: Integration | E2: #1 Capacity | F2: Jashim online in Banani; Bullet (3 seats) has an OPEN pool with 3 occupied seats; Shirin has a 1-seat REQUESTED ride. Second run: 2 seats occupied, a compatible 2-seat request. | G2: 1) Jashim accepts Shirin's request. 2) Reset to 2 occupied; Jashim accepts the 2-seat request. | H2: Both accepts return 409 CAPACITY_EXCEEDED; occupied_seats unchanged; no pool_member row created; requests stay REQUESTED. | I2: Not Written
A3: TC-02 | B3: Invalid state transitions are rejected without side effects | C3: BR-06, FR-POOL-05 | D3: Integration | E3: #2 Transitions | F3: Pool P OPEN with Nusrat MATCHED; a second pool P2 STARTED with Rafiq STARTED. | G3: 1) POST /pools/P/start. 2) Complete Nusrat while MATCHED. 3) Nusrat cancels after P2-style STARTED. 4) Accept a request into STARTED P2. 5) Arrive on a COMPLETED pool. | H3: Each returns 409 (INVALID_STATE_TRANSITION / POOL_NOT_OPEN); statuses, seats, fares and status_history unchanged. | I3: Written | J3: Ride level in test/rides/cancel.test.ts and test/domain/state-machine.test.ts; pool moves later | K3: 2026-09-24 partial
A4: TC-03 | B4: Nusrat's and Rafiq's pooled fares calculate correctly | C4: FR-FARE-01, BR-09, BR-10, BR-11, BR-13 | D4: Unit | E4: #3 Fares | F4: Default rates: base 3000, per km 1500, discount 2000 bps. | G4: Call fare(distance=3000m, seats=1, pooled=true/false) and fare(2500m, 1, true/false). | H4: Nusrat pooled 6600 / solo 7500; Rafiq pooled 6000 / solo 6750 paisa; breakdown components add up to total. | I4: Passing | J4: apps/api/test/domain/fare.test.ts | K4: 2026-09-24 passing (local + Docker)
A5: TC-04 | B5: Users can't modify or view another user's ride | C5: NFR-SEC-03, FR-AUTH-05 | D5: Integration | E5: #4 Authorization | F5: Nusrat has an active ride R; Jashim owns pool P; Kamal is online. | G5: 1) Rafiq GET/cancel R. 2) Nusrat calls POST /driver/requests/:id/accept. 3) Kamal POST /pools/P/arrive, /start, member complete. | H5: 1) 404 NOT_FOUND, R unchanged. 2) 403 FORBIDDEN. 3) 404/403 and P unchanged. | I5: Written | J5: Roles in test/auth/access.test.ts; ride ownership in test/rides/read.test.ts and cancel.test.ts; pools later | K5: 2026-09-24 partial
A6: TC-05 | B6: Cancellation rules hold | C6: BR-07, FR-PAX-08 | D6: Integration | E6: #5 Cancellation | F6: Rides for Nusrat in REQUESTED, MATCHED, DRIVER_ARRIVED and STARTED (separate setups). | G6: Nusrat cancels in each state. | H6: REQUESTED/MATCHED: CANCELLED, no charge. DRIVER_ARRIVED: CANCELLED with 2000-paisa fee. STARTED: 409 INVALID_STATE_TRANSITION. | I6: Written | J6: REQUESTED and STARTED in test/rides/cancel.test.ts, policy in test/domain/cancellation.test.ts; MATCHED and DRIVER_ARRIVED later | K6: 2026-09-24 partial
A7: TC-06 | B7: Concurrent claims can't corrupt pool capacity (last seat) | C7: NFR-CON-01, NFR-CON-02, NFR-CON-03, FR-POOL-09 | D7: Integration | E7: #6 Concurrency | F7: Bullet has 2/3 seats occupied; Nusrat and Shirin each have a compatible 1-seat REQUESTED ride. Second scenario: Jashim and Kamal both online in Banani, one open request. | G7: 1) Fire accept(Nusrat) and accept(Shirin) in parallel (Promise.all), repeat ≥20 times with fresh data. 2) Jashim and Kamal accept the same request in parallel. | H7: Every run: exactly one 200 and one 409; occupied_seats = 3 max; no CHECK violation. Scenario 2: one success, request in exactly one pool. | I7: Not Written
A8: TC-07 | B8: Database CHECK prevents over-capacity even bypassing the service | C8: FR-POOL-02, NFR-CON-01 | D8: Integration | E8: #1 Capacity | F8: Pool for Bullet with occupied_seats = 3. | G8: Direct SQL update occupied_seats = 4. | H8: Database rejects with CHECK constraint violation. | I8: Passing | J8: apps/api/test/db/constraints.test.ts | K8: 2026-09-24 passing (local + Docker)
A9: TC-08 | B9: Transition table is exhaustive (unit) | C9: BR-06, NFR-MNT-02 | D9: Unit | E9: #2 Transitions | F9: Pure canTransition(entity, from, to, actorRole). | G9: Iterate all (from, to, actor) combinations for ride request and pool. | H9: Only RT-01…RT-11 / PT-01…PT-06 are allowed; everything else is rejected. | I9: Passing | J9: apps/api/test/domain/state-machine.test.ts | K9: 2026-09-24 passing (local + Docker)
A10: TC-09 | B10: Fare locks at trip start; discount only if actually shared | C10: BR-12, FR-FARE-03 | D10: Integration | E10: #3 Fares | F10: Nusrat and Rafiq MATCHED in Bullet's pool. | G10: A) Arrive, start, check fares. B) Rafiq cancels before start, then arrive and start. | H10: A) Nusrat 6600, Rafiq 6000, pooled=true, rates snapshot stored. B) Nusrat 7500, pooled=false. | I10: Not Written
A11: TC-10 | B11: Multi-seat booking by one passenger is not pooling | C11: BR-12, BR-10 | D11: Unit | E11: #3 Fares | F11: Nusrat requests 2 seats Banani→Mohakhali alone. | G11: Start trip and compute fare. | H11: 15000 paisa (7500 × 2), pooled=false. | I11: Passing | J11: apps/api/test/domain/fare.test.ts (fare level); trip-start check with feature/driver-flow | K11: 2026-09-24 passing (local + Docker)
A12: TC-11 | B12: Locked fare is immutable after rate change | C12: FR-FARE-03 | D12: Integration | E12: #3 Fares | F12: Nusrat's fare locked at 6600. | G12: Change PER_KM_PAISA config to 2000 and re-read ride. | H12: Locked fare still 6600 with original rate snapshot. | I12: Not Written
A13: TC-12 | B13: Shirin's fares and zone distance lookup | C13: BR-09, BR-10, FR-FARE-01 | D13: Unit | E13: #3 Fares | F13: Zone table seeded. | G13: fare(Banani→Tejgaon, 1 seat, pooled / solo). | H13: Distance 5000 m; pooled 9000, solo 10500. | I13: Passing | J13: apps/api/test/domain/fare.test.ts, test/zones/zones.test.ts, test/fares/estimate.test.ts | K13: 2026-09-24 passing (local + Docker)
A14: TC-13 | B14: Passenger never sees co-rider personal data or fares | C14: FR-PAX-06, NFR-SEC-03 | D14: Integration | E14: #4 Authorization | F14: Nusrat and Rafiq in the same pool. | G14: Nusrat GET /rides/:id and /rides?scope=active. | H14: Response shows shared=true, coRiders=1, own fare only; no Rafiq name, destination or fare in the payload. | I14: Not Written
A15: TC-14 | B15: Cancellation fee recorded and debited | C15: FR-FARE-05, FR-PAY-05 | D15: Integration | E15: #5 Cancellation | F15: Nusrat (TeslaPay) and Rafiq (Cash) in DRIVER_ARRIVED. | G15: Both cancel. | H15: Nusrat: CANCELLATION_FEE charge 2000 + wallet ledger −2000. Rafiq: charge 2000 with payment status UNPAID. | I15: Not Written
A16: TC-15 | B16: Driver cancels pool before start; rejected after start | C16: FR-DRV-11, BR-07 | D16: Integration | E16: #5 Cancellation | F16: Pool with Nusrat and Rafiq in MATCHED; another pool STARTED. | G16: Jashim cancels the first pool; then tries to cancel the STARTED pool. | H16: First: pool CANCELLED, Nusrat & Rafiq back to REQUESTED, no charges. Second: 409. | I16: Not Written
A17: TC-16 | B17: Seats freed on cancel; pool auto-cancels when empty | C17: FR-POOL-06, FR-POOL-07 | D17: Integration | E17: #1 Capacity | F17: Pool with Nusrat and Rafiq (2/3). | G17: Rafiq cancels; then Nusrat cancels. | H17: After Rafiq: occupied 1. After Nusrat: pool CANCELLED (reason ALL_MEMBERS_CANCELLED); Jashim free to accept. | I17: Not Written
A18: TC-17 | B18: Concurrent passenger cancel vs driver accept | C18: NFR-CON-02 | D18: Integration | E18: #6 Concurrency | F18: Shirin REQUESTED; Jashim OPEN pool compatible. | G18: Run Shirin cancel and Jashim accept in parallel, ≥20 times. | H18: Exactly one wins; final state is either CANCELLED with no membership or MATCHED with membership — never both. | I18: Not Written
A19: TC-18 | B19: One active request per passenger (incl. double submit / retry) | C19: FR-PAX-04, BR-05, NFR-CON-04, NFR-CON-06 | D19: Integration | E19: #6 Concurrency | F19: Nusrat has no active ride. | G19: Submit two ride requests in parallel; then a third sequentially; then retry the first POST with the same Idempotency-Key (if implemented). | H19: Exactly one created; others 409 ACTIVE_REQUEST_EXISTS; idempotent retry returns the original request. | I19: Passing | J19: apps/api/test/rides/request.test.ts (no Idempotency-Key: retries rely on the unique index) | K19: 2026-09-24 passing (local + Docker)
A20: TC-19 | B20: One active pool per driver | C20: BR-04, NFR-CON-04 | D20: Integration | E20: #1 Capacity | F20: Jashim has an OPEN pool with a private (non-opt-in) request. | G20: Jashim accepts an unrelated request. | H20: 422 NOT_COMPATIBLE / 409; no second pool row for Jashim. | I20: Not Written
A21: TC-20 | B21: Matching rule: compatible vs incompatible requests | C21: BR-02, BR-03, BR-08, FR-POOL-03, FR-POOL-04 | D21: Unit | E21: Matching (PRD §4) | F21: Pool P from Banani with Nusrat → Mohakhali (opt-in). | G21: Check isCompatible for: Rafiq→Gulshan 1; Shirin→Tejgaon; Banani→Uttara; Gulshan 1→Mohakhali pickup; Rafiq opt-in=false; request 11 min after P created. | H21: Compatible: Rafiq, Shirin. Not compatible: Uttara, different pickup, opt-out, >10 min. API accept of an incompatible one returns 422. | I21: Not Written
A22: TC-21 | B22: Members can join only while pool OPEN | C22: FR-POOL-05 | D22: Integration | E22: #2 Transitions | F22: Pool DRIVER_ARRIVED with Nusrat; Rafiq REQUESTED compatible. | G22: Jashim accepts Rafiq. | H22: 409 POOL_NOT_OPEN. | I22: Not Written
A23: TC-22 | B23: Driver availability rules | C23: FR-DRV-02, FR-DRV-03 | D23: Integration | E23: Driver flow | F23: Jashim offline; later with active pool. | G23: Go online in Banani; go offline with active pool; go offline after completion. | H23: Online OK and audited; offline with active pool 409 ACTIVE_POOL_EXISTS; offline after completion OK. | I23: Not Written
A24: TC-23 | B24: Relevant request feed for Jashim | C24: FR-DRV-04 | D24: Integration | E24: Driver flow | F24: Requests: Nusrat (BAN→MHK), Rafiq (BAN→GL1), X (BAN→UTR), Y (GL1→MHK). Jashim online in Banani. | G24: GET /driver/requests before and after accepting Nusrat; also while offline. | H24: Before: Nusrat, Rafiq, X (not Y). After: Rafiq only (+ Shirin if present). Offline: 409 DRIVER_OFFLINE. | I24: Not Written
A25: TC-24 | B25: Expired requests can't be accepted | C25: NFR-REL-04, FR-PAX-03 | D25: Integration | E25: #2 Transitions | F25: Shirin's request requested_at = now − 16 min, sweeper not run. | G25: Jashim accepts; Shirin reads her ride. | H25: Accept 409; ride shows EXPIRED. | I25: Written | J25: Read side in test/rides/read.test.ts; the accept part with feature/tesla-pooling | K25: 2026-09-24 partial
A26: TC-25 | B26: Happy path: Nusrat and Rafiq share Bullet end to end | C26: FR-DRV-05, FR-DRV-06, FR-DRV-07, FR-DRV-08, FR-DRV-09, FR-POOL-01, FR-POOL-08, FR-POOL-10 | D26: E2E | E26: Scenario E1 | F26: Seeded personas; Jashim online in Banani. | G26: Nusrat requests; Rafiq requests; Jashim accepts both; arrive; start; drop Nusrat at Mohakhali; drop Rafiq at Gulshan 1. | H26: Statuses follow §5; pool shows 2/3 seats; Nusrat COMPLETED before Rafiq; pool auto-COMPLETED; Jashim's zone = Gulshan 1. | I26: Not Written
A27: TC-26 | B27: TeslaPay settlement and ledger integrity | C27: FR-PAY-03, FR-PAY-06, BR-15, NFR-CON-05 | D27: Integration | E27: Payment | F27: Nusrat wallet 50000 paisa, TeslaPay, pooled trip. | G27: Complete Nusrat. | H27: Balance 43400; RIDE_PAYMENT −6600 ledger row; balance = Σ ledger; payment PAID. | I27: Not Written
A28: TC-27 | B28: Cash payment pending then collected | C28: FR-PAY-04, FR-DRV-10, BR-16 | D28: Integration | E28: Payment | F28: Rafiq pays cash, pooled trip. | G28: Complete Rafiq; Jashim marks cash collected. | H28: PENDING_CASH 6000 → PAID; audited. | I28: Not Written
A29: TC-28 | B29: Insufficient TeslaPay balance at request | C29: FR-PAX-05 | D29: Integration | E29: Payment | F29: Shirin wallet 5000 paisa; solo estimate 10500. | G29: Shirin requests with TESLAPAY. | H29: 422 INSUFFICIENT_BALANCE; no ride created. | I29: Not Written
A30: TC-29 | B30: Wallet top-up limits | C30: FR-PAY-01, FR-PAY-02, BR-17 | D30: Integration | E30: Payment | F30: Nusrat wallet. | G30: Top up ৳500, ৳10, ৳6000. | H30: ৳500 credited (+50000, TOPUP row); ৳10 and ৳6000 → 400. | I30: Not Written
A31: TC-30 | B31: Audit trail fully reconstructs the ride | C31: FR-HIST-01, FR-HIST-02, FR-HIST-04 | D31: Integration | E31: History | F31: Run TC-25. | G31: Query status_history for Nusrat's ride and the pool. | H31: One row per transition with actor, role, reason, timestamp; no update/delete path exists; ride reconstructable from records. | I31: Not Written
A32: TC-31 | B32: Passenger sign-up validation | C32: FR-AUTH-01 | D32: Integration | E32: Auth | F32: Nusrat already exists. | G32: Sign up new passenger; duplicate e-mail; 6-char password. | H32: 201 + wallet ৳0; 409; 400. | I32: Passing | J32: apps/api/test/auth/sign-up.test.ts | K32: 2026-09-24 passing (local + Docker)
A33: TC-32 | B33: Sign-in, sign-out and /me | C33: FR-AUTH-02, FR-AUTH-03, FR-AUTH-04, NFR-SEC-02 | D33: Integration | E33: Auth | F33: Seeded Jashim. | G33: Login ok; login wrong password; /me; logout; /me again; call protected endpoint without session. | H33: 200 with role DRIVER + vehicle; 401 generic; 401 after logout; 401 unauthenticated. | I33: Passing | J33: apps/api/test/auth/sessions.test.ts | K33: 2026-09-24 passing (local + Docker)
A34: TC-33 | B34: Input validation at the API boundary | C34: FR-PAX-03, NFR-SEC-04 | D34: Integration | E34: Validation | F34: Nusrat signed in. | G34: Create ride with pickup = destination; seats 0; seats 4; unknown zone; extra field. | H34: 400 VALIDATION_ERROR with field details each time. | I34: Passing | J34: apps/api/test/rides/request.test.ts | K34: 2026-09-24 passing (local + Docker)
A35: TC-34 | B35: Standard error format and no leaks | C35: NFR-REL-01, NFR-SEC-09 | D35: Integration | E35: Errors | F35: Production mode. | G35: Trigger 400, 404, 409 and a forced 500. | H35: Body {error:{code,message,details},requestId}; 500 has no stack trace. | I35: Written | J35: apps/api/test/app.test.ts (404, malformed JSON, requestId); 409/500 cases added with later modules | K35: 2026-09-24 passing
A36: TC-35 | B36: Zones list and fare estimate (solo & pooled with breakdown) | C36: FR-PAX-01, FR-PAX-02, FR-FARE-02, FR-FARE-04 | D36: Integration | E36: #3 Fares | F36: Nusrat signed in; zones seeded. | G36: GET /zones; POST /fares/estimate BAN→MHK 1 seat. | H36: 10 zones with code/name/coords; estimate solo 7500, pooled 6600, breakdown base/distance/discount. | I36: Passing | J36: apps/api/test/zones/zones.test.ts, apps/api/test/fares/estimate.test.ts | K36: 2026-09-24 passing (local + Docker)
A37: TC-36 | B37: docker compose up on a fresh clone | C37: NFR-POR-01, NFR-REL-02, DR-09 | D37: Manual | E37: Docker | F37: Clean machine with Docker only. | G37: Clone; cp .env.example .env; docker compose up. | H37: All services healthy; migrations + seed applied; Nusrat and Jashim can sign in. | I37: Not Written
A38: TC-37 | B38: Seed is idempotent and uses the reference personas | C38: NFR-POR-03, DR-15, FR-AUTH-06, BR-08 | D38: Manual | E38: Docker | F38: Stack running. | G38: Run seed twice; search repo for user1/driver1. | H38: No duplicates or errors; personas present; no placeholders found. | I38: Passing | J38: apps/api/test/db/seed.test.ts (automated; no user1/driver1 in seed data) | K38: 2026-09-24 passing (local + Docker)
A39: TC-38 | B39: Login rate limiting | C39: NFR-SEC-07 | D39: Integration | E39: Security | F39: — | G39: 11 failed logins within 1 minute from one IP. | H39: 11th returns 429 RATE_LIMITED. | I39: Passing | J39: apps/api/test/auth/rate-limit.test.ts | K39: 2026-09-24 passing (local + Docker)
A40: TC-39 | B40: Passenger history and ride detail | C40: FR-PAX-09, FR-PAX-10, FR-HIST-03 | D40: Integration | E40: History | F40: Nusrat has 2 past rides; Rafiq has 1. | G40: Nusrat GET /rides?scope=history and a detail. | H40: Only Nusrat's rides, newest first, with timeline and fare breakdown. | I40: Passing | J40: apps/api/test/rides/read.test.ts | K40: 2026-09-24 passing (local + Docker)
...

Sheet Assumptions_Decisions
A1: ID | B1: Kind | C1: Statement | D1: Rationale / resolution | E1: Alternatives considered | F1: Related reqs | G1: Status | H1: Date | I1: Notes / who confirmed
A2: A-01 | B2: Assumption | C2: Geography is a fixed list of 10 Dhaka zones with a hand-authored, symmetric distance table and an adjacency list (§13.3). | D2: PRD §4 says not to fight map APIs. It is also deterministic and hand-checkable. | F2: BR-08, BR-09 | G2: Proposed | H2: 2026-09-23
A3: A-02 | B3: Assumption | C3: A passenger's pickup is the zone itself. There is no street address or pin. | D3: Keeps pooling pickup to a single stop. | F3: BR-02 | G3: Proposed | H3: 2026-09-23
A4: A-03 | B4: Assumption | C4: A driver owns exactly one Tesla, and its capacity is fixed (Bullet = 3). | D4: PRD §3 says "own a Tesla with fixed capacity". | F4: FR-DRV-01, BR-01 | G4: Proposed | H4: 2026-09-23
A5: A-04 | B5: Assumption | C5: A passenger may book 1 to capacity seats for companions without accounts. The fare is per seat. | D5: Common real-world case; PRD says "seats". | F5: FR-PAX-03, BR-10 | G5: Proposed | H5: 2026-09-23
A6: A-05 | B6: Assumption | C6: Drivers and their Teslas are seeded. There is no driver self-sign-up or KYC. | D6: PRD lists only "sign in" for drivers. | F6: FR-AUTH-06, FR-AUTH-07 | G6: Proposed | H6: 2026-09-23
A7: A-06 | B7: Assumption | C7: Each person has one role. A user cannot be both passenger and driver. | D7: Simplifies authorization. | F7: NFR-SEC-03 | G7: Proposed | H7: 2026-09-23
A8: A-07 | B8: Assumption | C8: Pooling is opt-in per request, and the default is on. | D8: PRD says "when it makes sense". Privacy-minded passengers can opt out. | F8: FR-POOL-04, BR-02 | G8: Proposed | H8: 2026-09-23
A9: A-08 | B9: Assumption | C9: Arrival and start are pool-level, because members share the pickup zone. Drop-off is per passenger. | D9: Real trips drop riders at different points. | F9: FR-DRV-07, FR-DRV-08, FR-DRV-09 | G9: Proposed | H9: 2026-09-23
A10: A-09 | B10: Assumption | C10: A passenger sees that the ride is shared and the number of co-riders, but not their names, destinations or fares. | D10: PRD §2: "their own fare and status, not anyone else's". | F10: FR-PAX-06 | G10: Proposed | H10: 2026-09-23
A11: A-10 | B11: Assumption | C11: The driver sees each member's name, destination, seats, fare and payment method. | D11: Needed to run the trip and collect cash. | F11: FR-DRV-06 | G11: Proposed | H11: 2026-09-23
A12: A-11 | B12: Assumption | C12: Clients refresh by polling every 3–5 s. There are no WebSockets in the MVP. | D12: PRD §9: avoid complexity without a reason. Polling is enough at MVP scale. | F12: FR-PAX-07, NFR-PERF-03 | G12: Proposed | H12: 2026-09-23
A13: A-12 | B13: Assumption | C13: New members can join only while the pool is OPEN, i.e. before the driver arrives. | D13: Avoids delaying passengers who are already waiting. | F13: FR-POOL-05 | G13: Proposed | H13: 2026-09-23
... A19: A-18 | B19: Assumption | C19: Ratings, the admin console, notifications and surge pricing are out of scope. | D19: PRD lists them as optional. MVP focus. | F19: FR-AUTH-07 | G19: Proposed | H19: 2026-09-23
A20: A-19 | B20: Assumption | C20: Gender is self-declared and optional, with no verification. Misdeclaration is a known limitation. | D20: Identity verification (KYC) is out of scope (A-05, A-18). | F20: FR-AUTH-01, FR-PAX-11 | G20: Confirmed | H20: 2026-09-24 | I20: Confirmed by product owner (optional gender)
A21: A-20 | B21: Assumption | C21: Gender is personal data. It is never shown to co-riders or included in their API responses. Drivers see only the pool's restriction badge. | D21: Data minimisation (A-09, NFR-SEC-03). | F21: FR-PAX-11, NFR-SEC-03 | G21: Proposed | H21: 2026-09-24
A22: A-21 | B22: Assumption | C22: The same-gender option restricts co-riders only, not the driver. | D22: Both driver personas are male; a driver rule would make restricted rides unmatchable in the MVP. | F22: BR-18 | G22: Confirmed | H22: 2026-09-24 | I22: Confirmed by product owner (passengers only)
A23: D-01 | B23: Decision | C23: The SRS follows ISO/IEC/IEEE 29148 as Markdown in the repo, with an Excel RTM. | D23: Reviewable in git history, sits next to the code, and the industry-standard structure. | E23: Word document; Excel only | F23: DR-18 | G23: Confirmed | H23: 2026-09-23 | I23: Confirmed by product owner in SRS planning session
A24: D-02 | B24: Decision | C24: Geography is zones plus a distance table plus an adjacency list. | D24: Hand-verifiable fares and no dependency on a map service. | E24: Lat/long with haversine; a free map | F24: BR-08, BR-09 | G24: Confirmed | H24: 2026-09-23 | I24: Confirmed by product owner in SRS planning session
A25: D-03 | B25: Decision | C25: Matching uses the same pickup zone, same or adjacent destinations, and a 10-minute window. | D25: Simple, transparent and consistent, and it handles the overlapping Nusrat/Rafiq trips. | E25: Detour percentage; same pickup only | F25: BR-02 | G25: Confirmed | H25: 2026-09-23 | I25: Confirmed by product owner in SRS planning session
A26: D-04 | B26: Decision | C26: The driver accepts each request explicitly into the pool. | D26: Matches the PRD's driver flow ("accept a ride/pool") and gives the driver control. | E26: Auto-join after the first accept; full auto-dispatch | F26: FR-DRV-05, BR-03 | G26: Confirmed | H26: 2026-09-23 | I26: Confirmed by product owner in SRS planning session
A27: D-05 | B27: Decision | C27: Money is stored as integer paisa (BIGINT). | D27: Exact integer arithmetic, no float bugs in JS, and identical results in JS and SQL. | E27: DECIMAL(10,2) | F27: BR-14, FR-FARE-06 | G27: Confirmed | H27: 2026-09-23 | I27: Confirmed by product owner in SRS planning session
A28: D-06 | B28: Decision | C28: Fare = base + per-km charge − 20 % of the distance charge when pooled, per seat. | D28: Easy to check by hand, the discount scales with distance, and the base covers the pickup cost. | E28: Flat discount; split the shared leg | F28: BR-10, BR-11 | G28: Confirmed | H28: 2026-09-23 | I28: Confirmed by product owner in SRS planning session
A29: D-07 | B29: Decision | C29: The fare locks at trip start. | D29: The discount is given only when the ride really was shared, and the price is fixed during the ride. | E29: Lock at match; compute at completion | F29: BR-12, FR-FARE-03 | G29: Confirmed | H29: 2026-09-23 | I29: Confirmed by product owner in SRS planning session
A30: D-08 | B30: Decision | C30: Cancellation is free before arrival, ৳20 after arrival, and not allowed after start. | D30: Fair to both sides and discourages no-shows. | E30: Free until start; only before match | F30: BR-07 | G30: Confirmed | H30: 2026-09-23 | I30: Confirmed by product owner in SRS planning session
A31: D-09 | B31: Decision | C31: Payment is cash or the simulated TeslaPay wallet with a ledger. | D31: Covers both PRD options and shows ledger integrity. | E31: Cash only; wallet only | F31: FR-PAY-01…06 | G31: Confirmed | H31: 2026-09-23 | I31: Confirmed by product owner in SRS planning session
A32: D-10 | B32: Decision | C32: The API style is REST with action sub-resources for transitions. | D32: Simple resources, explicit guarded commands, and easy to test with curl or HTTP clients. | E32: GraphQL; RPC | F32: §8.2 | G32: Proposed | H32: 2026-09-23
A33: D-11 | B33: Decision | C33: Status updates use polling. | D33: No extra infrastructure; enough for the MVP (A-11). | E33: WebSockets, SSE | F33: FR-PAX-07 | G33: Proposed | H33: 2026-09-23
A34: D-12 | B34: Decision | C34: There are two linked state machines (ride request and pool). | D34: Pooled trips have passenger-level and trip-level events that cannot share one status. | E34: A single ride status | F34: §5, BR-06 | G34: Proposed | H34: 2026-09-23 | I34: Chosen by product owner in architecture session
A35: D-13 | B35: Decision | C35: The DBMS is PostgreSQL 16 (ADR-0002). | D35: CHECK constraints, partial unique indexes, row locks and transactional DDL directly support the integrity rules. | E35: MySQL, SQLite, MongoDB | F35: DC-03, NFR-CON-04, ADR-0002 | G35: Proposed | H35: 2026-09-23 | I35: Chosen by product owner in architecture session
A36: D-14 | B36: Decision | C36: The system is a modular monolith: Next.js web + one Express API + PostgreSQL (ADR-0001). | D36: Every invariant fits in one ACID transaction, with no distributed consistency (PRD §9). | E36: Next.js-only; microservices | F36: DC-05, DR-14 | G36: Proposed | H36: 2026-09-24 | I36: Chosen by product owner in architecture session
A37: D-15 | B37: Decision | C37: The API is built with Express 5 + TypeScript (ADR-0003). | D37: No hidden control flow, a large ecosystem, and explicit layering that is simple to trace and maintain. | E37: NestJS; Fastify | F37: DC-02, DC-07 | G37: Confirmed | H37: 2026-09-24 | I37: Chosen by product owner in architecture session
A38: D-16 | B38: Decision | C38: Data access uses Prisma, with CHECK constraints, partial unique indexes and triggers in hand-written SQL migrations (ADR-0004). | D38: Type-safe DX for most queries. Raw SQL is visible exactly where the integrity guarantees are implemented. | E38: Drizzle; Knex; TypeORM | F38: NFR-CON-04, NFR-POR-03, NFR-SEC-08 | G38: Confirmed | H38: 2026-09-24 | I38: Chosen by product owner in architecture session
A39: D-17 | B39: Decision | C39: Auth uses opaque DB-backed sessions (SHA-256 hash stored) in an httpOnly cookie, behind a same-origin Next.js /api proxy (ADR-0005). | D39: Real logout; a DB leak exposes no usable tokens; first-party cookies across different hosts. | E39: JWT in cookie; Auth.js/Lucia | F39: FR-AUTH-02, FR-AUTH-03, NFR-SEC-06 | G39: Confirmed | H39: 2026-09-24 | I39: Chosen by product owner in architecture session
A40: D-18 | B40: Decision | C40: Concurrency uses row locks in the fixed order driver → pool → ride → wallet, compare-and-set transitions and DB constraints. Expiry is checked in the accept CAS, plus a 60 s in-process sweeper (ADR-0006). | D40: Deterministic outcome for the last-seat race, with no extra infrastructure. | E40: Optimistic versioning; SERIALIZABLE; Redis lock | F40: NFR-CON-01, NFR-CON-02, NFR-CON-03, NFR-REL-04 | G40: Proposed | H40: 2026-09-24
A41: D-19 | B41: Decision | C41: The repo is an npm-workspaces monorepo: apps/web, apps/api, packages/shared (Zod, enums, transition tables) (ADR-0008). | D41: One source for schemas, enums and transition tables across web and API. | E41: Turborepo/Nx; two repos | F41: NFR-MNT-01, NFR-MNT-03 | G41: Proposed | H41: 2026-09-24
A42: D-20 | B42: Decision | C42: Deployment is Docker Compose now, then Vercel + Railway + Supabase on free tiers, with a verify-no-payment guardrail (ADR-0009). | D42: The primary run path (docker compose up) never depends on third parties, and the same images run in the cloud. | E42: Render-only; Vercel + Render + Neon | F42: NFR-POR-01, NFR-POR-04, DC-04, DR-11 | G42: Confirmed | H42: 2026-09-24 | I42: Chosen by product owner in architecture session
A43: D-21 | B43: Decision | C43: Tests use Vitest + Supertest against a real PostgreSQL test DB (ADR-0011). | D43: Locks and constraints can only be proven against the real engine. | E43: Jest; mocks/SQLite; Testcontainers | F43: DR-10, NFR-MNT-04 | G43: Proposed | H43: 2026-09-24
A44: D-22 | B44: Decision | C44: The frontend uses the Next.js App Router + TanStack Query (polling) + react-hook-form + Tailwind CSS (ADR-0012). | D44: Built-in loading/error states and polling; a small, maintainable UI stack. | E44: Vite + React Router; SWR; component libraries | F44: DC-01, FR-PAX-07, NFR-USA-01 | G44: Proposed | H44: 2026-09-24
A45: D-23 | B45: Decision | C45: Schema choices: pool_members link table, pools.capacity snapshot, driver_profiles table, zone code natural key, UUID ids, polymorphic append-only status_history (ERD §8). | D45: Row-local CHECK for capacity, re-matching history, driver-only ownership that is structural. | E45: ride_requests.pool_id; capacity via trigger; driver columns on users | F45: FR-POOL-02, FR-POOL-10, FR-HIST-02 | G45: Proposed | H45: 2026-09-24
...

Sheet Implementation_Tasks
A1: Task ID | B1: Branch | C1: Description | D1: Req IDs | E1: Planned commit message | F1: Estimate (h) | G1: Status | H1: Actual commit(s) / PR | I1: Notes
A2: T-01 | B2: feature/srs-docs | C2: Write SRS (ISO/IEC/IEEE 29148) and traceability workbook | D2: DR-18 | E2: docs(srs): add software requirements specification and traceability workbook | F2: 6 | G2: In Review | I2: SRS v0.2 synced with ERD on 2026-09-24
A3: T-02 | B3: feature/architecture-docs | C3: Architecture diagram, ERD, tech-choice justifications (resolve OI-01..OI-03) | D3: DR-06, DR-07, DR-14, DC-01, DC-02, DC-03, DC-05, DC-07 | E3: docs(architecture): add system architecture diagram and ERD | F3: 5 | G3: In Review | H3: docs/ARCHITECTURE.md, docs/ERD.md, docs/adr/0001–0012 | I3: Drafted 2026-09-24; awaiting review
A4: T-03 | B4: feature/project-setup | C4: Scaffold web (Next.js) and api (Node.js, TypeScript) workspaces; lint, format, folder structure | D4: NFR-MNT-01, NFR-MNT-03, DC-01, DC-02 | E4: chore(repo): scaffold web and api workspaces | F4: 3 | G4: Done | H4: f221565 chore(repo), 9ddba2e docs(conventions) on feature/project-setup | I4: Also added docs/CODING_CONVENTIONS.md and config/rules.ts
A5: T-04 | B5: feature/project-setup | C5: API foundation: error handler & format, requestId, structured logging, security headers, CORS, schema validation | D5: NFR-REL-01, NFR-OBS-01, NFR-OBS-02, NFR-OBS-03, NFR-SEC-04, NFR-SEC-06, NFR-SEC-08, NFR-SEC-09 | E5: feat(api): add error handling, structured logging and request validation | F5: 4 | G5: Done | H5: 51da796 feat(api), 28caad4 refactor(api) on feature/project-setup | I5: Tests: apps/api/test/app.test.ts
A6: T-05 | B6: feature/project-setup | C6: Docker Compose (db, api, web), health checks, .env.example, /health endpoint | D6: NFR-POR-01, NFR-POR-02, NFR-REL-02, NFR-REL-03, NFR-SEC-05, DR-09, DC-03, DC-06 | E6: build(docker): add compose setup for api, web and postgres | F6: 4 | G6: Done | H6: 7d59b8d build(docker) on feature/project-setup | I6: Verified: 3 containers healthy, web page shows 'API ok', tests pass in container
A7: T-06 | B7: feature/db-schema | C7: Migrations for all entities with CHECK, unique/partial-unique constraints and indexes (SRS §7) | D7: NFR-CON-04, NFR-PERF-02, NFR-POR-03, FR-FARE-06, BR-14, FR-PAY-06, FR-HIST-02, FR-POOL-09, FR-POOL-10, BR-18 | E7: feat(db): add schema migrations with capacity and uniqueness constraints | F7: 6 | G7: Done | H7: e7db6c7 feat(db) schema, 77d5ab5 feat(db) integrity migration, 5c0b0e9 feat(db) helpers — feature/db-schema | I7: Prisma migrate diff shows no drift against the hand-written objects
A8: T-07 | B8: feature/db-schema | C8: Seed zones, distances, adjacency and reference personas (Nusrat, Rafiq, Shirin, Jashim/Bullet, Kamal/Toofan) with wallets | D8: BR-08, FR-AUTH-06, DR-15, NFR-POR-03 | E8: feat(seed): add Dhaka zones and reference persona seed data | F8: 3 | G8: Done | H8: b9272b5 feat(seed) — feature/db-schema | I8: Seed runs on container start; idempotent (TC-37)
A9: T-08 | B9: feature/passenger-auth | C9: Sign-up, sign-in, sign-out, /me with hashed passwords and secure session | D9: FR-AUTH-01, FR-AUTH-02, FR-AUTH-03, FR-AUTH-04, NFR-SEC-01, NFR-SEC-02, NFR-SEC-06 | E9: feat(auth): add passenger signup and login endpoints | F9: 5 | G9: Done | H9: 6ee7875 feat(shared), 0fccd56 feat(auth), 347e153 feat(auth) — feature/passenger-auth | I9: Sign-up, sign-in, sessions, sign-out, /me
A10: T-09 | B10: feature/passenger-auth | C10: Role guards, ownership checks, login rate limiting + authorization tests | D10: FR-AUTH-05, NFR-SEC-03, NFR-SEC-07 | E10: feat(auth): enforce role-based access and rate-limit login | F10: 3 | G10: Done | H10: 347e153 feat(auth) guards, cea26a4 feat(auth) rate limit, 07b28b6 test(auth) — feature/passenger-auth | I10: requireAuth/requireRole; 10 attempts/min per IP behind one trusted proxy hop
A11: T-10 | B11: feature/zones-fares | C11: Pure fare engine in paisa + unit tests for worked examples | D11: FR-FARE-01, BR-09, BR-10, BR-11, BR-12, BR-13, NFR-MNT-02 | E11: feat(fare): add paisa-based fare calculator with pool discount | F11: 3 | G11: Done | H11: b4e67b9 feat(fare), 1be55c0 test(fare), d9ff25f test(fare) — feature/zones-fares | I11: computeFare() and roundHalfUpDiv() on whole paisa; rates from CURRENT_FARE_RATES
A12: T-11 | B12: feature/zones-fares | C12: Zones and fare-estimate endpoints | D12: FR-PAX-01, FR-PAX-02, FR-FARE-02, FR-FARE-04 | E12: feat(fare): add zones and fare estimate endpoints | F12: 2 | G12: Done | H12: 2a5c39d feat(fare), 86a24c5 fix(api), 63be8bb test(fare) — feature/zones-fares | I12: GET /api/zones, POST /api/fares/estimate; zone reference data cached in memory
A13: T-12 | B13: feature/ride-request | C13: Ride & pool state machine module with transactional audit writer | D13: BR-06, FR-HIST-01, FR-HIST-02, FR-HIST-03, NFR-CON-02, NFR-MNT-02 | E13: feat(ride): add ride and pool state machines with audit trail | F13: 4 | G13: Done | H13: 97a8fb6 feat(ride) state machines, 97e9a70 feat(audit) — feature/ride-request | I13: Transition tables shared with the web app; audit writer inside the caller's transaction; WARN log for 409/422
A14: T-13 | B14: feature/ride-request | C14: Passenger ride endpoints: create, active/history, detail, cancel (with fee), expiry | D14: FR-PAX-03, FR-PAX-04, FR-PAX-05, FR-PAX-06, FR-PAX-08, FR-PAX-09, FR-PAX-10, BR-05, BR-07, FR-FARE-05, FR-HIST-04, NFR-REL-04, NFR-CON-06, FR-PAX-11 | E14: feat(ride): add passenger ride request lifecycle endpoints | F14: 6 | G14: In Progress | H14: 0896c40 feat(ride), e32e7bb fix(ride), dcc02ed feat(ride), 75785c0 test(ride) — feature/ride-request | I14: Create, list, detail, expiry and REQUESTED cancel done; cancelling MATCHED/DRIVER_ARRIVED (seat release, fee) comes with feature/tesla-pooling and feature/driver-flow
